Workbook

Sheet Web Dev Pricing Calculator
A1: Client Name | B1: Client Value
A2: Project Name | B2: Project Value
A3: Date | B3: =TODAY()
A4: Quote Valid Until | B4: =B3+30
A5: Contact Email | B5: Email Value
A7: BASE PACKAGE SELECTION
A8: Package Type | B8: Select (X) | C8: Base Price | D8: Your Price
A9: Starter Site (4-6 pages) | C9: 2500 | D9: =IF(B9="X",C9,0)
A10: Growth Site (8-20 pages) | C10: 7500 | D10: =IF(B10="X",C10,0)
A11: Custom Site (complex) | C11: 18000 | D11: =IF(B11="X",C11,0)
A13: Selected Base: | D13: =SUM(D9:D11)
A15: PAGE COUNT ADJUSTMENTS
A16: Pages | B16: Select (X) | C16: Package | D16: Price | E16: Your Price
A17: 4-6 pages | C17: Starter | D17: 0 | E17: =IF(B17="X",D17,0)
A18: 8-10 pages | C18: Growth/Custom | D18: 0 | E18: =IF(B18="X",D18,0)
A19: 11-15 pages | C19: Growth | D19: 1500 | E19: =IF(B19="X",D19,0)
A20: 11-15 pages | C20: Custom | D20: 2000 | E20: =IF(B20="X",D20,0)
A21: 16-20 pages | C21: Growth | D21: 3000 | E21: =IF(B21="X",D21,0)
A22: 16-20 pages | C22: Custom | D22: 4000 | E22: =IF(B22="X",D22,0)
A23: 21-30 pages | C23: Custom | D23: 6000 | E23: =IF(B23="X",D23,0)
A24: 31+ pages | C24: Custom | D24: 10000 | E24: =IF(B24="X",D24,0)
A26: Page Count Total: | E26: =SUM(E17:E24)
A28: E-COMMERCE FEATURES
A29: Feature | B29: Select (X) | C29: Price | D29: Your Price
A30: No e-commerce | C30: 0 | D30: =IF(B30="X",C30,0)
A31: Simple store (5-20 products) | C31: 2750 | D31: =IF(B31="X",C31,0)
A32: Medium store (21-100 products) | C32: 5500 | D32: =IF(B32="X",C32,0)
A33: Large store (100+ products) | C33: 11500 | D33: =IF(B33="X",C33,0)
A34: Product variants (sizes/colors) | C34: 1000 | D34: =IF(B34="X",C34,0)
A35: Inventory management | C35: 1500 | D35: =IF(B35="X",C35,0)
A36: Subscriptions/recurring billing | C36: 2000 | D36: =IF(B36="X",C36,0)
A37: Advanced shipping calculations | C37: 1000 | D37: =IF(B37="X",C37,0)
A38: Multi-currency | C38: 1500 | D38: =IF(B38="X",C38,0)
A39: Product reviews system | C39: 800 | D39: =IF(B39="X",C39,0)
A41: E-commerce Total: | D41: =SUM(D30:D39)
A43: CONTENT PREPARATION
A44: Service | B44: Select (X) | C44: Price | D44: Your Price
A45: Content ready (organized) | C45: 0 | D45: =IF(B45="X",C45,0)
A46: Partial (needs organization) | C46: 750 | D46: =IF(B46="X",C46,0)
A47: Need help (writing/sourcing) | C47: 2250 | D47: =IF(B47="X",C47,0)
...

Sheet Client Quote
A1: Client Name: | B1: ='Web Dev Pricing Calculator'!B1
A2: Project Name: | B2: ='Web Dev Pricing Calculator'!B2
A3: Quote Date: | B3: ='Web Dev Pricing Calculator'!B3
A4: Quote Valid Until: | B4: ='Web Dev Pricing Calculator'!B4
A6: PROJECT COST SUMMARY
A8: Base Package: | B8: ='Web Dev Pricing Calculator'!D12
A9: Page Adjustments: | B9: ='Web Dev Pricing Calculator'!E25
A10: E-Commerce: | B10: ='Web Dev Pricing Calculator'!D39
A11: Content: | B11: ='Web Dev Pricing Calculator'!D49
A12: Features: | B12: ='Web Dev Pricing Calculator'!D72
A13: Design: | B13: ='Web Dev Pricing Calculator'!D83
A14: Technical: | B14: ='Web Dev Pricing Calculator'!D93
A15: Migration: | B15: ='Web Dev Pricing Calculator'!D104
A17: SUBTOTAL: | B17: =SUM(B8:B15)
A18: Timeline Adjustment: | B18: ='Web Dev Pricing Calculator'!D129
A19: Discounts: | B19: ='Web Dev Pricing Calculator'!D139
A21: PROJECT TOTAL: | B21: =B17+B18+B19
